============================= test session starts ==============================
platform linux -- Python 3.12.3, pytest-8.4.2, pluggy-1.6.0 -- /mnt/c/Users/DaviCastroSamora/Documents/SamoraDC/RustAlgorithmTrading/venv/bin/python3
cachedir: .pytest_cache
rootdir: /mnt/c/Users/DaviCastroSamora/Documents/SamoraDC/RustAlgorithmTrading/tests
configfile: pytest.ini
collecting ... collected 0 items / 1 error

==================================== ERRORS ====================================
_________________ ERROR collecting unit/test_race_condition.py _________________
ImportError while importing test module '/mnt/c/Users/DaviCastroSamora/Documents/SamoraDC/RustAlgorithmTrading/tests/unit/test_race_condition.py'.
Hint: make sure your test modules/packages have valid Python names.
Traceback:
venv/lib/python3.12/site-packages/_pytest/python.py:498: in importtestmodule
    mod = import_path(
venv/lib/python3.12/site-packages/_pytest/pathlib.py:587: in import_path
    importlib.import_module(module_name)
/usr/lib/python3.12/importlib/__init__.py:90: in import_module
    return _bootstrap._gcd_import(name[level:], package, level)
           ^^^^^^^^^^^^^^^^^^^^^^^^^^^^^^^^^^^^^^^^^^^^^^^^^^^^
<frozen importlib._bootstrap>:1387: in _gcd_import
    ???
<frozen importlib._bootstrap>:1360: in _find_and_load
    ???
<frozen importlib._bootstrap>:1331: in _find_and_load_unlocked
    ???
<frozen importlib._bootstrap>:935: in _load_unlocked
    ???
venv/lib/python3.12/site-packages/_pytest/assertion/rewrite.py:186: in exec_module
    exec(co, module.__dict__)
tests/unit/test_race_condition.py:18: in <module>
    from src.backtesting.portfolio_handler import PortfolioHandler
src/__init__.py:8: in <module>
    from src.api.alpaca_client import AlpacaClient
src/api/__init__.py:3: in <module>
    from src.api.alpaca_client import AlpacaClient
src/api/alpaca_client.py:9: in <module>
    from alpaca.trading.client import TradingClient
E   ModuleNotFoundError: No module named 'alpaca'
=========================== short test summary info ============================
ERROR tests/unit/test_race_condition.py
!!!!!!!!!!!!!!!!!!!! Interrupted: 1 error during collection !!!!!!!!!!!!!!!!!!!!
============================== 1 error in 15.69s ===============================
